Workbook
Name ___Dia01: [1]!_xlbgnm.Dia01
Name ___Dia03: [1]!_xlbgnm.Dia03
Name ___Dia04: [1]!_xlbgnm.Dia04
Name __JOB2: #REF!
Name __JOB2: #REF!
Name _1Module1__2__.SetColor: #N/A
Name _1Module1__2__.SetColor: #N/A
Name _Dia01: [1]!_xlbgnm.Dia01
Name _Dia03: [1]!_xlbgnm.Dia03
Name _Dia04: [1]!_xlbgnm.Dia04
Name _JOB2: #REF!
Name _JOB2: #REF!
Name a: #REF!
Name a: #REF!
Name aa: #REF!
Name aa: #REF!
Name aaa: #REF!
Name aaa: #REF!
Name aaaa: #REF!
Name aaaa: #REF!
Name abc: #N/A
Name AD: '[2]Prod''s Info'!#REF!
Name AD: #REF!
Name asdfasdfgasdgfasdgf: #N/A
Name asdfasdfgasdgfasdgf: #N/A
Name b: #REF!
Name b: #REF!
Name bo: #REF!
Name bo: #REF!
Name Bom: #N/A
Name CEL_SELECT_SR45: [3]!CEL_SELECT_SR45
Name CEL_SELECT_SR46: [3]!CEL_SELECT_SR46
Name CEL_SELECT_SR47: [3]!CEL_SELECT_SR47
Name CEL_SELECT_SR48: [3]!CEL_SELECT_SR48
Name CEL_SELECT_SR49: [3]!CEL_SELECT_SR49
Name CEL_SELECT_ST4: [3]!CEL_SELECT_ST4
Name CEL_SELECT_ST5: [3]!CEL_SELECT_ST5
Name CEL_SELECT_ST6: [3]!CEL_SELECT_ST6
Name CEL_SELECT_ST7: [3]!CEL_SELECT_ST7
Name CEL_SELECT_ST8: [3]!CEL_SELECT_ST8
Name CEL_SELECT_ST9: [3]!CEL_SELECT_ST9
Name dddd: #REF!
Name dddd: #REF!
Name dfasdfasdf: #N/A
Name dfasdfasdf: #N/A
Name ｄｓｆ: #N/A
Name ｄｓｆ: #N/A
Name f_01: #REF!
Name f_01: #REF!
Name f_02: #REF!
Name f_02: #REF!
Name f_03: #REF!
Name f_03: #REF!
Name f_04: #REF!
Name f_04: #REF!
Name f_05: #REF!
Name f_05: #REF!
Name f_06: #REF!
Name f_06: #REF!
Name f_07: #REF!

Sheet Density-8digital code
A1: LV-Code | B1: Re-blend of | C1: SAP code | D1: Product Name | E1: Density @15
A2: LV-001 | C2: 30465008 | D2: =VLOOKUP(A2,'[2]Prod''s Info'!$A:$K,4,0) -> KAYABA OIL G-10 | E2: 0.8739
A3: LV-002 | C3: 30460130 | D3: SS7G HYDRAULIC FLUID | E3: 0.8712
A4: LV-003 | C4: 30460132 | D4: SS8G HYDRAULIC FLUID | E4: 0.8647
A5: LV-004 | C5: 34059004 | D5: =VLOOKUP(A5,'[2]Prod''s Info'!$A:$K,4,0) -> HONDA 4T SJ 10W-30 MA | E5: 0.8708
A6: LV-007 | C6: 34195015 | D6: =VLOOKUP(A6,'[2]Prod''s Info'!$A:$K,4,0) -> YAMALUBE 4T SJ 10W-40 MB | E6: 0.8656
A7: LV-009 | C7: 30305025 | D7: =VLOOKUP(A7,'[2]Prod''s Info'!$A:$K,4,0) -> IDEMITSU RACING GEAR GL-5 80W-90 | E7: 0.8854
A8: LV-010 | C8: 34059010 | D8: =VLOOKUP(A8,'[2]Prod''s Info'!$A:$K,4,0) -> HONDA 4T SJ 20W-40 MA | E8: 0.8824
A9: LV-012 | B9: LV-179 | C9: 34215008 | D9: =VLOOKUP(A9,'[2]Prod''s Info'!$A:$K,4,0) -> MITSUBISHI GASOLINE ENGINE OIL SM/CF 10W-40 SUPER | E9: 0.8531
A10: LV-013 | C10: 32050333 | D10: =VLOOKUP(A10,'[2]Prod''s Info'!$A:$K,4,0) -> DAPHNE SUPER GEAR OIL 150 | E10: 0.8872
A11: LV-014 | C11: 32050359 | D11: =VLOOKUP(A11,'[2]Prod''s Info'!$A:$K,4,0) -> DAPHNE SUPER GEAR OIL 220 | E11: 0.8938
A12: LV-015 | C12: 32050375 | D12: =VLOOKUP(A12,'[2]Prod''s Info'!$A:$K,4,0) -> DAPHNE SUPER GEAR OIL 320 | E12: 0.9001
A13: LV-018 | C13: 32240106 | D13: =VLOOKUP(A13,'[2]Prod''s Info'!$A:$K,4,0) -> DAPHNE SUPER HYDRO 32A | E13: 0.858
A14: LV-019 | C14: 32240116 | D14: =VLOOKUP(A14,'[2]Prod''s Info'!$A:$K,4,0) -> DAPHNE SUPER HYDRO 46A | E14: 0.8652
A15: LV-020 | C15: 32240122 | D15: =VLOOKUP(A15,'[2]Prod''s Info'!$A:$K,4,0) -> DAPHNE SUPER HYDRO 68A | E15: 0.8725
A16: LV-021 | C16: 32310138 | D16: =VLOOKUP(A16,'[2]Prod''s Info'!$A:$K,4,0) -> DAPHNE MECHANIC OIL 68 | E16: 0.8694
A17: LV-022 | C17: 32310113 | D17: =VLOOKUP(A17,'[2]Prod''s Info'!$A:$K,4,0) -> DAPHNE MECHANIC OIL 32 | E17: 0.8554
A18: LV-023 | C18: 32295008 | D18: =VLOOKUP(A18,'[2]Prod''s Info'!$A:$K,4,0) -> DAPHNE MULTIWAY 68MT | E18: 0.8831
A19: LV-024 | C19: 32280248 | D19: =VLOOKUP(A19,'[2]Prod''s Info'!$A:$K,4,0) -> DAPHNE SUPER MULTI OIL 32 | E19: 0.8552
A20: LV-025 | C20: 32280264 | D20: =VLOOKUP(A20,'[2]Prod''s Info'!$A:$K,4,0) -> DAPHNE SUPER MULTI OIL 68 | E20: 0.8712
A21: LV-026 | C21: 32353408 | D21: =VLOOKUP(A21,'[2]Prod''s Info'!$A:$K,4,0) -> DAPHNE SUPER TURBINE OIL MG32 | E21: 0.8442
... A25: LV-030 | C25: 32690117 | D25: =VLOOKUP(A25,'[2]Prod''s Info'!$A:$K,4,0) -> DAPHNE HI-TEMP OIL A | E25: 0.8918
A26: LV-034 | B26: LV-001 | C26: 34195016 | D26: =VLOOKUP(A26,'[2]Prod''s Info'!$A:$K,4,0) -> YAMALUBE FRONT FORK OIL G-10 | E26: 0.8739
A27: LV-036 | B27: LV-020 | C27: 32245013 | D27: =VLOOKUP(A27,'[2]Prod''s Info'!$A:$K,4,0) -> KOBELCO GENUINE HYDRAULIC OIL #68 | E27: 0.8725
A28: LV-038 | C28: 32690269 | D28: =VLOOKUP(A28,'[2]Prod''s Info'!$A:$K,4,0) -> DAPHNE HI-TEMP OIL AM | E28: 0.8903
A29: LV-039 | C29: 30185008 | D29: =VLOOKUP(A29,'[2]Prod''s Info'!$A:$K,4,0) -> APOLLOIL MULTI RUNNER DH-1 15W-40 | E29: 0.8792
A30: LV-040 | B30: LV-039 | C30: 34185034 | D30: =VLOOKUP(A30,'[2]Prod''s Info'!$A:$K,4,0) -> KOBELCO GENUINE DIESEL ENGINE OIL DH-1 15W-40 | E30: 0.8792
A31: LV-042 | B31: JA-151 | C31: 34055046 | D31: =VLOOKUP(A31,'[2]Prod''s Info'!$A:$K,4,0) -> ACURA POWER STEERING FLUID | E31: 0.8554
A32: LV-044 | C32: 34051530 | D32: HONDA ULTRA LEO SP 0W-20 | E32: 0.8459
A33: LV-045 | B33: LV-135 | C33: 34050024 | D33: =VLOOKUP(A33,'[2]Prod''s Info'!$A:$K,4,0) -> ACURA ATF DW-1 | E33: 0.8513
A34: LV-046 | C34: 34155022 | D34: =VLOOKUP(A34,'[2]Prod''s Info'!$A:$K,4,0) -> MAZDA GOLDEN ECO SM 0W-20 | E34: 0.8521
A35: LV-052 | C35: 34055094 | D35: =VLOOKUP(A35,'[2]Prod''s Info'!$A:$K,4,0) -> HONDA VTEC LEV SL 5W-40 FULLY SYN. | E35: 0.8488
A36: LV-053 | C36: 34151178 | D36: =VLOOKUP(A36,'[2]Prod''s Info'!$A:$K,4,0) -> MAZDA ATF M-V | E36: 0.8616
A37: LV-054 | C37: 34150423 | D37: =VLOOKUP(A37,'[2]Prod''s Info'!$A:$K,4,0) -> MAZDA ATF FZ | E37: 0.8512
A38: LV-055 | C38: 34055099 | D38: =VLOOKUP(A38,'[2]Prod''s Info'!$A:$K,4,0) -> HONDA GENUINE OIL SM OW-20 | E38: 0.85
A39: LV-056 | C39: 30460213 | D39: =VLOOKUP(A39,'[2]Prod''s Info'!$A:$K,4,0) -> KAYABA No.3 I-2 HYDRAULIC FLUID | E39: 0.8816
A40: LV-061 | C40: 30041107 | D40: IDEMITSU MULTI CVTF | E40: 0.8525
A41: LV-062 | C41: 30305030 | D41: =VLOOKUP(A41,'[2]Prod''s Info'!$A:$K,4,0) -> IDEMITSU GEAR GL-4 90 | E41: 0.8953
A42: LV-063 | C42: 30305031 | D42: =VLOOKUP(A42,'[2]Prod''s Info'!$A:$K,4,0) -> IDEMITSU GEAR GL-4 1 40 | E42: 0.9023
A43: LV-064 | C43: 30305043 | D43: =VLOOKUP(A43,'[2]Prod''s Info'!$A:$K,4,0) -> IDEMITSU GEAR GL-5 90 | E43: 0.8971
...
